Workbook

Sheet DATA
A1: NPWP Pemotong | C1: 0668176225064000
B3: Masa Pajak | C3: Tahun Pajak | D3: NPWP | E3: ID TKU Penerima Penghasilan | F3: Status PTKP | G3: Fasilitas | H3: Kode Objek Pajak | I3: Penghasilan | J3: Deemed | K3: Tarif | L3: Jenis Dok. Referensi | M3: Nomor Dok. Referensi | N3: Tanggal Dok. Referensi | O3: ID TKU Pemotong | P3: Tanggal Pemotongan | R3: DPP | S3: JNSTARIF | T3: TER A | U3: TER B | V3: TER C | W3: PS17 | X3: HARIAN | Y3: PESANGON | Z3: PENSIUN
B4: 5 | C4: 2026 | D4: 3374061210850003 | E4: 3374061210850003000000 | F4: K/0 | G4: N/A | H4: 21-100-35 | I4: 1375000 | J4: =VLOOKUP(H4,REF!$A$2:$D$33,3,0) -> 100 | K4: =IF(S4="TER",IF(OR(F4="TK/0",F4="TK/1",F4="K/0",F4="HB/0",F4="HB/1"),T4,IF(OR(F4="TK/2",F4="TK/3",F4="K/1",F4="K/2",F4="HB/2",F4="HB/3"),U4,V4)),IF(S4="PS17",W4,IF(S4="HARIAN",X4,IF(S4="PESANGON",Y4,IF(S4="PENSIUN",Z4,S4))))) -> 0 | L4: Other | M4: - | N4: 46173 | O4: 0668176225064000000000 | P4: 46173 | R4: =Table1[[#This Row],[Penghasilan]]*Table1[[#This Row],[Deemed]]/100 -> 1375000 | S4: =VLOOKUP(H4,REF!$A$2:$D$43,4,0) -> TER | T4: =IF(R4<=5400000,0,IF(AND(R4>5400000,R4<=5650000),0.25,IF(AND(R4>5650000,R4<=5950000),0.5,IF(AND(R4>5950000,R4<=6300000),0.75,IF(AND(R4>6300000,R4<=6750000),1,IF(AND(R4>6750000,R4<=7500000),1.25,IF(AND(R4>7500000,R4<=8550000),1.5,IF(AND(R4>8550000,R4<=9650000),1.75,IF(AND(R4>9650000,R4<=10050000),2,IF(AND(R4>10050000,R4<=10350000),2.25,IF(AND(R4>10350000,R4<=10700000),2.5,IF(AND(R4>10700000,R4<=11050000),3,IF(AND(R4>11050000,R4<=11600000),3.5,IF(AND(R4>11600000,R4<=12500000),4,IF(AND(R4>12500000,R4<=13750000),5,IF(AND(R4>13750000,R4<=15100000),6,IF(AND(R4>15100000,R4<=16950000),7,IF(AND(R4>16950000,R4<=19750000),8,IF(AND(R4>19750000,R4<=24150000),9,IF(AND(R4>24150000,R4<=26450000),10,IF(AND(R4>26450000,R4<=28000000),11,IF(AND(R4>28000000,R4<=30050000),12,IF(AND(R4>30050000,R4<=32400000),13,IF(AND(R4>32400000,R4<=35400000),14,IF(AND(R4>35400000,R4<=39100000),15,IF(AND(R4>39100000,R4<=43850000),16,IF(AND(R4>43850000,R4<=47800000),17,IF(AND(R4>47800000,R4<=51400000),18,IF(AND(R4>51400000,R4<=56300000),19,IF(AND(R4>56300000,R4<=62200000),20,IF(AND(R4>62200000,R4<=68600000),21,IF(AND(R4>68600000,R4<=77500000),22,IF(AND(R4>77500000,R4<=89000000),23,IF(AND(R4>89000000,R4<=103000000),24,IF(AND(R4>103000000,R4<=125000000),25,IF(AND(R4>125000000,R4<=157000000),26,IF(AND(R4>157000000,R4<=206000000),27,IF(AND(R4>206000000,R4<=337000000),28,IF(AND(R4>337000000,R4<=454000000),29,IF(AND(R4>454000000,R4<=550000000),30,IF(AND(R4>550000000,R4<=695000000),31,IF(AND(R4>695000000,R4<=910000000),32,IF(AND(R4>910000000,R4<=1400000000),33,34))))))))))))))))))))))))))))))))))))))))))) -> 0 | U4: =IF(R4<=6200000,0,IF(AND(R4>6200000,R4<=6500000),0.25,IF(AND(R4>6500000,R4<=6850000),0.5,IF(AND(R4>6850000,R4<=7300000),0.75,IF(AND(R4>7300000,R4<=9200000),1,IF(AND(R4>9200000,R4<=10750000),1.5,IF(AND(R4>10750000,R4<=11250000),2,IF(AND(R4>11250000,R4<=11600000),2.5,IF(AND(R4>11600000,R4<=12600000),3,IF(AND(R4>12600000,R4<=13600000),4,IF(AND(R4>13600000,R4<=14950000),5,IF(AND(R4>14950000,R4<=16400000),6,IF(AND(R4>16400000,R4<=18450000),7,IF(AND(R4>18450000,R4<=21850000),8,IF(AND(R4>21850000,R4<=26000000),9,IF(AND(R4>26000000,R4<=27700000),10,IF(AND(R4>27700000,R4<=29350000),11,IF(AND(R4>29350000,R4<=31450000),12,IF(AND(R4>31450000,R4<=33950000),13,IF(AND(R4>33950000,R4<=37100000),14,IF(AND(R4>37100000,R4<=41100000),15,IF(AND(R4>41100000,R4<=45800000),16,IF(AND(R4>45800000,R4<=49500000),17,IF(AND(R4>49500000,R4<=53800000),18,IF(AND(R4>53800000,R4<=58500000),19,IF(AND(R4>58500000,R4<=64000000),20,IF(AND(R4>64000000,R4<=71000000),21,IF(AND(R4>71000000,R4<=80000000),22,IF(AND(R4>80000000,R4<=93000000),23,IF(AND(R4>93000000,R4<=109000000),24,IF(AND(R4>109000000,R4<=129000000),25,IF(AND(R4>129000000,R4<=163000000),26,IF(AND(R4>163000000,R4<=211000000),27,IF(AND(R4>211000000,R4<=374000000),28,IF(AND(R4>374000000,R4<=459000000),29,IF(AND(R4>459000000,R4<=555000000),30,IF(AND(R4>555000000,R4<=704000000),31,IF(AND(R4>704000000,R4<=957000000),32,IF(AND(R4>957000000,R4<=1405000000),33,34))))))))))))))))))))))))))))))))))))))) -> 0 | V4: =IF(R4<=6600000,0,IF(AND(R4>6600000,R4<=6950000),0.25,IF(AND(R4>6950000,R4<=7350000),0.5,IF(AND(R4>7350000,R4<=7800000),0.75,IF(AND(R4>7800000,R4<=8850000),1,IF(AND(R4>8850000,R4<=9800000),1.25,IF(AND(R4>9800000,R4<=10950000),1.5,IF(AND(R4>10950000,R4<=11200000),1.75,IF(AND(R4>11200000,R4<=12050000),2,IF(AND(R4>12050000,R4<=12950000),3,IF(AND(R4>12950000,R4<=14150000),4,IF(AND(R4>14150000,R4<=15550000),5,IF(AND(R4>15550000,R4<=17050000),6,IF(AND(R4>17050000,R4<=19500000),7,IF(AND(R4>19500000,R4<=22700000),8,IF(AND(R4>22700000,R4<=26600000),9,IF(AND(R4>26600000,R4<=28100000),10,IF(AND(R4>28100000,R4<=30100000),11,IF(AND(R4>30100000,R4<=32600000),12,IF(AND(R4>32600000,R4<=35400000),13,IF(AND(R4>35400000,R4<=38900000),14,IF(AND(R4>38900000,R4<=43000000),15,IF(AND(R4>43000000,R4<=47400000),16,IF(AND(R4>47400000,R4<=51200000),17,IF(AND(R4>51200000,R4<=55800000),18,IF(AND(R4>55800000,R4<=60400000),19,IF(AND(R4>60400000,R4<=66700000),20,IF(AND(R4>66700000,R4<=74500000),21,IF(AND(R4>74500000,R4<=83200000),22,IF(AND(R4>83200000,R4<=95600000),23,IF(AND(R4>95600000,R4<=110000000),24,IF(AND(R4>110000000,R4<=134000000),25,IF(AND(R4>134000000,R4<=169000000),26,IF(AND(R4>169000000,R4<=221000000),27,IF(AND(R4>221000000,R4<=390000000),28,IF(AND(R4>390000000,R4<=463000000),29,IF(AND(R4>463000000,R4<=561000000),30,IF(AND(R4>561000000,R4<=709000000),31,IF(AND(R4>709000000,R4<=965000000),32,IF(AND(R4>965000000,R4<=1419000000),33,34)))))))))))))))))))))))))))))))))))))))) -> 0 | W4: =IF(R4<=60000000,5,IF(AND(R4>60000000,R4<=250000000),15,IF(AND(R4>250000000,R4<=500000000),25,IF(AND(R4>500000000,R4<=5000000000),30,35)))) -> 5 | X4: =IF(R4<=450000,0,IF(AND(R4>450000,R4<=2500000),0.5,0)) -> 0.5 | Y4: =IF(R4<=50000000,0,IF(AND(R4>50000000,R4<=100000000),5,IF(AND(R4>100000000,R4<=500000000),15,25))) -> 0 | Z4: =IF(R4<=50000000,0,5) -> 0
B5: 5 | C5: 2026 | D5: 3201130705990006 | E5: 3201130705990006000000 | F5: TK/0 | G5: N/A | H5: 21-100-35 | I5: 6264837.8 | J5: =VLOOKUP(H5,REF!$A$2:$D$33,3,0) -> 100 | K5: =IF(S5="TER",IF(OR(F5="TK/0",F5="TK/1",F5="K/0",F5="HB/0",F5="HB/1"),T5,IF(OR(F5="TK/2",F5="TK/3",F5="K/1",F5="K/2",F5="HB/2",F5="HB/3"),U5,V5)),IF(S5="PS17",W5,IF(S5="HARIAN",X5,IF(S5="PESANGON",Y5,IF(S5="PENSIUN",Z5,S5))))) -> 0.75 | L5: Other | M5: - | N5: 46173 | O5: 0668176225064000000000 | P5: 46173 | R5: =Table1[[#This Row],[Penghasilan]]*Table1[[#This Row],[Deemed]]/100 -> 6264837.8 | S5: =VLOOKUP(H5,REF!$A$2:$D$43,4,0) -> TER | T5: =IF(R5<=5400000,0,IF(AND(R5>5400000,R5<=5650000),0.25,IF(AND(R5>5650000,R5<=5950000),0.5,IF(AND(R5>5950000,R5<=6300000),0.75,IF(AND(R5>6300000,R5<=6750000),1,IF(AND(R5>6750000,R5<=7500000),1.25,IF(AND(R5>7500000,R5<=8550000),1.5,IF(AND(R5>8550000,R5<=9650000),1.75,IF(AND(R5>9650000,R5<=10050000),2,IF(AND(R5>10050000,R5<=10350000),2.25,IF(AND(R5>10350000,R5<=10700000),2.5,IF(AND(R5>10700000,R5<=11050000),3,IF(AND(R5>11050000,R5<=11600000),3.5,IF(AND(R5>11600000,R5<=12500000),4,IF(AND(R5>12500000,R5<=13750000),5,IF(AND(R5>13750000,R5<=15100000),6,IF(AND(R5>15100000,R5<=16950000),7,IF(AND(R5>16950000,R5<=19750000),8,IF(AND(R5>19750000,R5<=24150000),9,IF(AND(R5>24150000,R5<=26450000),10,IF(AND(R5>26450000,R5<=28000000),11,IF(AND(R5>28000000,R5<=30050000),12,IF(AND(R5>30050000,R5<=32400000),13,IF(AND(R5>32400000,R5<=35400000),14,IF(AND(R5>35400000,R5<=39100000),15,IF(AND(R5>39100000,R5<=43850000),16,IF(AND(R5>43850000,R5<=47800000),17,IF(AND(R5>47800000,R5<=51400000),18,IF(AND(R5>51400000,R5<=56300000),19,IF(AND(R5>56300000,R5<=62200000),20,IF(AND(R5>62200000,R5<=68600000),21,IF(AND(R5>68600000,R5<=77500000),22,IF(AND(R5>77500000,R5<=89000000),23,IF(AND(R5>89000000,R5<=103000000),24,IF(AND(R5>103000000,R5<=125000000),25,IF(AND(R5>125000000,R5<=157000000),26,IF(AND(R5>157000000,R5<=206000000),27,IF(AND(R5>206000000,R5<=337000000),28,IF(AND(R5>337000000,R5<=454000000),29,IF(AND(R5>454000000,R5<=550000000),30,IF(AND(R5>550000000,R5<=695000000),31,IF(AND(R5>695000000,R5<=910000000),32,IF(AND(R5>910000000,R5<=1400000000),33,34))))))))))))))))))))))))))))))))))))))))))) -> 0.75 | U5: =IF(R5<=6200000,0,IF(AND(R5>6200000,R5<=6500000),0.25,IF(AND(R5>6500000,R5<=6850000),0.5,IF(AND(R5>6850000,R5<=7300000),0.75,IF(AND(R5>7300000,R5<=9200000),1,IF(AND(R5>9200000,R5<=10750000),1.5,IF(AND(R5>10750000,R5<=11250000),2,IF(AND(R5>11250000,R5<=11600000),2.5,IF(AND(R5>11600000,R5<=12600000),3,IF(AND(R5>12600000,R5<=13600000),4,IF(AND(R5>13600000,R5<=14950000),5,IF(AND(R5>14950000,R5<=16400000),6,IF(AND(R5>16400000,R5<=18450000),7,IF(AND(R5>18450000,R5<=21850000),8,IF(AND(R5>21850000,R5<=26000000),9,IF(AND(R5>26000000,R5<=27700000),10,IF(AND(R5>27700000,R5<=29350000),11,IF(AND(R5>29350000,R5<=31450000),12,IF(AND(R5>31450000,R5<=33950000),13,IF(AND(R5>33950000,R5<=37100000),14,IF(AND(R5>37100000,R5<=41100000),15,IF(AND(R5>41100000,R5<=45800000),16,IF(AND(R5>45800000,R5<=49500000),17,IF(AND(R5>49500000,R5<=53800000),18,IF(AND(R5>53800000,R5<=58500000),19,IF(AND(R5>58500000,R5<=64000000),20,IF(AND(R5>64000000,R5<=71000000),21,IF(AND(R5>71000000,R5<=80000000),22,IF(AND(R5>80000000,R5<=93000000),23,IF(AND(R5>93000000,R5<=109000000),24,IF(AND(R5>109000000,R5<=129000000),25,IF(AND(R5>129000000,R5<=163000000),26,IF(AND(R5>163000000,R5<=211000000),27,IF(AND(R5>211000000,R5<=374000000),28,IF(AND(R5>374000000,R5<=459000000),29,IF(AND(R5>459000000,R5<=555000000),30,IF(AND(R5>555000000,R5<=704000000),31,IF(AND(R5>704000000,R5<=957000000),32,IF(AND(R5>957000000,R5<=1405000000),33,34))))))))))))))))))))))))))))))))))))))) -> 0.25 | V5: =IF(R5<=6600000,0,IF(AND(R5>6600000,R5<=6950000),0.25,IF(AND(R5>6950000,R5<=7350000),0.5,IF(AND(R5>7350000,R5<=7800000),0.75,IF(AND(R5>7800000,R5<=8850000),1,IF(AND(R5>8850000,R5<=9800000),1.25,IF(AND(R5>9800000,R5<=10950000),1.5,IF(AND(R5>10950000,R5<=11200000),1.75,IF(AND(R5>11200000,R5<=12050000),2,IF(AND(R5>12050000,R5<=12950000),3,IF(AND(R5>12950000,R5<=14150000),4,IF(AND(R5>14150000,R5<=15550000),5,IF(AND(R5>15550000,R5<=17050000),6,IF(AND(R5>17050000,R5<=19500000),7,IF(AND(R5>19500000,R5<=22700000),8,IF(AND(R5>22700000,R5<=26600000),9,IF(AND(R5>26600000,R5<=28100000),10,IF(AND(R5>28100000,R5<=30100000),11,IF(AND(R5>30100000,R5<=32600000),12,IF(AND(R5>32600000,R5<=35400000),13,IF(AND(R5>35400000,R5<=38900000),14,IF(AND(R5>38900000,R5<=43000000),15,IF(AND(R5>43000000,R5<=47400000),16,IF(AND(R5>47400000,R5<=51200000),17,IF(AND(R5>51200000,R5<=55800000),18,IF(AND(R5>55800000,R5<=60400000),19,IF(AND(R5>60400000,R5<=66700000),20,IF(AND(R5>66700000,R5<=74500000),21,IF(AND(R5>74500000,R5<=83200000),22,IF(AND(R5>83200000,R5<=95600000),23,IF(AND(R5>95600000,R5<=110000000),24,IF(AND(R5>110000000,R5<=134000000),25,IF(AND(R5>134000000,R5<=169000000),26,IF(AND(R5>169000000,R5<=221000000),27,IF(AND(R5>221000000,R5<=390000000),28,IF(AND(R5>390000000,R5<=463000000),29,IF(AND(R5>463000000,R5<=561000000),30,IF(AND(R5>561000000,R5<=709000000),31,IF(AND(R5>709000000,R5<=965000000),32,IF(AND(R5>965000000,R5<=1419000000),33,34)))))))))))))))))))))))))))))))))))))))) -> 0 | W5: =IF(R5<=60000000,5,IF(AND(R5>60000000,R5<=250000000),15,IF(AND(R5>250000000,R5<=500000000),25,IF(AND(R5>500000000,R5<=5000000000),30,35)))) -> 5 | X5: =IF(R5<=450000,0,IF(AND(R5>450000,R5<=2500000),0.5,0)) -> 0 | Y5: =IF(R5<=50000000,0,IF(AND(R5>50000000,R5<=100000000),5,IF(AND(R5>100000000,R5<=500000000),15,25))) -> 0 | Z5: =IF(R5<=50000000,0,5) -> 0
B6: 5 | C6: 2026 | D6: 3205280402920004 | E6: 3205280402920004000000 | F6: TK/0 | G6: N/A | H6: 21-100-35 | I6: 2751922.2 | J6: =VLOOKUP(H6,REF!$A$2:$D$33,3,0) -> 100 | K6: =IF(S6="TER",IF(OR(F6="TK/0",F6="TK/1",F6="K/0",F6="HB/0",F6="HB/1"),T6,IF(OR(F6="TK/2",F6="TK/3",F6="K/1",F6="K/2",F6="HB/2",F6="HB/3"),U6,V6)),IF(S6="PS17",W6,IF(S6="HARIAN",X6,IF(S6="PESANGON",Y6,IF(S6="PENSIUN",Z6,S6))))) -> 0 | L6: Other | M6: - | N6: 46173 | O6: 0668176225064000000000 | P6: 46173 | R6: =Table1[[#This Row],[Penghasilan]]*Table1[[#This Row],[Deemed]]/100 -> 2751922.2 | S6: =VLOOKUP(H6,REF!$A$2:$D$43,4,0) -> TER | T6: =IF(R6<=5400000,0,IF(AND(R6>5400000,R6<=5650000),0.25,IF(AND(R6>5650000,R6<=5950000),0.5,IF(AND(R6>5950000,R6<=6300000),0.75,IF(AND(R6>6300000,R6<=6750000),1,IF(AND(R6>6750000,R6<=7500000),1.25,IF(AND(R6>7500000,R6<=8550000),1.5,IF(AND(R6>8550000,R6<=9650000),1.75,IF(AND(R6>9650000,R6<=10050000),2,IF(AND(R6>10050000,R6<=10350000),2.25,IF(AND(R6>10350000,R6<=10700000),2.5,IF(AND(R6>10700000,R6<=11050000),3,IF(AND(R6>11050000,R6<=11600000),3.5,IF(AND(R6>11600000,R6<=12500000),4,IF(AND(R6>12500000,R6<=13750000),5,IF(AND(R6>13750000,R6<=15100000),6,IF(AND(R6>15100000,R6<=16950000),7,IF(AND(R6>16950000,R6<=19750000),8,IF(AND(R6>19750000,R6<=24150000),9,IF(AND(R6>24150000,R6<=26450000),10,IF(AND(R6>26450000,R6<=28000000),11,IF(AND(R6>28000000,R6<=30050000),12,IF(AND(R6>30050000,R6<=32400000),13,IF(AND(R6>32400000,R6<=35400000),14,IF(AND(R6>35400000,R6<=39100000),15,IF(AND(R6>39100000,R6<=43850000),16,IF(AND(R6>43850000,R6<=47800000),17,IF(AND(R6>47800000,R6<=51400000),18,IF(AND(R6>51400000,R6<=56300000),19,IF(AND(R6>56300000,R6<=62200000),20,IF(AND(R6>62200000,R6<=68600000),21,IF(AND(R6>68600000,R6<=77500000),22,IF(AND(R6>77500000,R6<=89000000),23,IF(AND(R6>89000000,R6<=103000000),24,IF(AND(R6>103000000,R6<=125000000),25,IF(AND(R6>125000000,R6<=157000000),26,IF(AND(R6>157000000,R6<=206000000),27,IF(AND(R6>206000000,R6<=337000000),28,IF(AND(R6>337000000,R6<=454000000),29,IF(AND(R6>454000000,R6<=550000000),30,IF(AND(R6>550000000,R6<=695000000),31,IF(AND(R6>695000000,R6<=910000000),32,IF(AND(R6>910000000,R6<=1400000000),33,34))))))))))))))))))))))))))))))))))))))))))) -> 0 | U6: =IF(R6<=6200000,0,IF(AND(R6>6200000,R6<=6500000),0.25,IF(AND(R6>6500000,R6<=6850000),0.5,IF(AND(R6>6850000,R6<=7300000),0.75,IF(AND(R6>7300000,R6<=9200000),1,IF(AND(R6>9200000,R6<=10750000),1.5,IF(AND(R6>10750000,R6<=11250000),2,IF(AND(R6>11250000,R6<=11600000),2.5,IF(AND(R6>11600000,R6<=12600000),3,IF(AND(R6>12600000,R6<=13600000),4,IF(AND(R6>13600000,R6<=14950000),5,IF(AND(R6>14950000,R6<=16400000),6,IF(AND(R6>16400000,R6<=18450000),7,IF(AND(R6>18450000,R6<=21850000),8,IF(AND(R6>21850000,R6<=26000000),9,IF(AND(R6>26000000,R6<=27700000),10,IF(AND(R6>27700000,R6<=29350000),11,IF(AND(R6>29350000,R6<=31450000),12,IF(AND(R6>31450000,R6<=33950000),13,IF(AND(R6>33950000,R6<=37100000),14,IF(AND(R6>37100000,R6<=41100000),15,IF(AND(R6>41100000,R6<=45800000),16,IF(AND(R6>45800000,R6<=49500000),17,IF(AND(R6>49500000,R6<=53800000),18,IF(AND(R6>53800000,R6<=58500000),19,IF(AND(R6>58500000,R6<=64000000),20,IF(AND(R6>64000000,R6<=71000000),21,IF(AND(R6>71000000,R6<=80000000),22,IF(AND(R6>80000000,R6<=93000000),23,IF(AND(R6>93000000,R6<=109000000),24,IF(AND(R6>109000000,R6<=129000000),25,IF(AND(R6>129000000,R6<=163000000),26,IF(AND(R6>163000000,R6<=211000000),27,IF(AND(R6>211000000,R6<=374000000),28,IF(AND(R6>374000000,R6<=459000000),29,IF(AND(R6>459000000,R6<=555000000),30,IF(AND(R6>555000000,R6<=704000000),31,IF(AND(R6>704000000,R6<=957000000),32,IF(AND(R6>957000000,R6<=1405000000),33,34))))))))))))))))))))))))))))))))))))))) -> 0 | V6: =IF(R6<=6600000,0,IF(AND(R6>6600000,R6<=6950000),0.25,IF(AND(R6>6950000,R6<=7350000),0.5,IF(AND(R6>7350000,R6<=7800000),0.75,IF(AND(R6>7800000,R6<=8850000),1,IF(AND(R6>8850000,R6<=9800000),1.25,IF(AND(R6>9800000,R6<=10950000),1.5,IF(AND(R6>10950000,R6<=11200000),1.75,IF(AND(R6>11200000,R6<=12050000),2,IF(AND(R6>12050000,R6<=12950000),3,IF(AND(R6>12950000,R6<=14150000),4,IF(AND(R6>14150000,R6<=15550000),5,IF(AND(R6>15550000,R6<=17050000),6,IF(AND(R6>17050000,R6<=19500000),7,IF(AND(R6>19500000,R6<=22700000),8,IF(AND(R6>22700000,R6<=26600000),9,IF(AND(R6>26600000,R6<=28100000),10,IF(AND(R6>28100000,R6<=30100000),11,IF(AND(R6>30100000,R6<=32600000),12,IF(AND(R6>32600000,R6<=35400000),13,IF(AND(R6>35400000,R6<=38900000),14,IF(AND(R6>38900000,R6<=43000000),15,IF(AND(R6>43000000,R6<=47400000),16,IF(AND(R6>47400000,R6<=51200000),17,IF(AND(R6>51200000,R6<=55800000),18,IF(AND(R6>55800000,R6<=60400000),19,IF(AND(R6>60400000,R6<=66700000),20,IF(AND(R6>66700000,R6<=74500000),21,IF(AND(R6>74500000,R6<=83200000),22,IF(AND(R6>83200000,R6<=95600000),23,IF(AND(R6>95600000,R6<=110000000),24,IF(AND(R6>110000000,R6<=134000000),25,IF(AND(R6>134000000,R6<=169000000),26,IF(AND(R6>169000000,R6<=221000000),27,IF(AND(R6>221000000,R6<=390000000),28,IF(AND(R6>390000000,R6<=463000000),29,IF(AND(R6>463000000,R6<=561000000),30,IF(AND(R6>561000000,R6<=709000000),31,IF(AND(R6>709000000,R6<=965000000),32,IF(AND(R6>965000000,R6<=1419000000),33,34)))))))))))))))))))))))))))))))))))))))) -> 0 | W6: =IF(R6<=60000000,5,IF(AND(R6>60000000,R6<=250000000),15,IF(AND(R6>250000000,R6<=500000000),25,IF(AND(R6>500000000,R6<=5000000000),30,35)))) -> 5 | X6: =IF(R6<=450000,0,IF(AND(R6>450000,R6<=2500000),0.5,0)) -> 0 | Y6: =IF(R6<=50000000,0,IF(AND(R6>50000000,R6<=100000000),5,IF(AND(R6>100000000,R6<=500000000),15,25))) -> 0 | Z6: =IF(R6<=50000000,0,5) -> 0
B7: 5 | C7: 2026 | D7: 3174090510760006 | E7: 3174090510760006000000 | F7: TK/0 | G7: N/A | H7: 21-100-35 | I7: 6264837.8 | J7: =VLOOKUP(H7,REF!$A$2:$D$33,3,0) -> 100 | K7: =IF(S7="TER",IF(OR(F7="TK/0",F7="TK/1",F7="K/0",F7="HB/0",F7="HB/1"),T7,IF(OR(F7="TK/2",F7="TK/3",F7="K/1",F7="K/2",F7="HB/2",F7="HB/3"),U7,V7)),IF(S7="PS17",W7,IF(S7="HARIAN",X7,IF(S7="PESANGON",Y7,IF(S7="PENSIUN",Z7,S7))))) -> 0.75 | L7: Other | M7: - | N7: 46173 | O7: 0668176225064000000000 | P7: 46173 | R7: =Table1[[#This Row],[Penghasilan]]*Table1[[#This Row],[Deemed]]/100 -> 6264837.8 | S7: =VLOOKUP(H7,REF!$A$2:$D$43,4,0) -> TER | T7: =IF(R7<=5400000,0,IF(AND(R7>5400000,R7<=5650000),0.25,IF(AND(R7>5650000,R7<=5950000),0.5,IF(AND(R7>5950000,R7<=6300000),0.75,IF(AND(R7>6300000,R7<=6750000),1,IF(AND(R7>6750000,R7<=7500000),1.25,IF(AND(R7>7500000,R7<=8550000),1.5,IF(AND(R7>8550000,R7<=9650000),1.75,IF(AND(R7>9650000,R7<=10050000),2,IF(AND(R7>10050000,R7<=10350000),2.25,IF(AND(R7>10350000,R7<=10700000),2.5,IF(AND(R7>10700000,R7<=11050000),3,IF(AND(R7>11050000,R7<=11600000),3.5,IF(AND(R7>11600000,R7<=12500000),4,IF(AND(R7>12500000,R7<=13750000),5,IF(AND(R7>13750000,R7<=15100000),6,IF(AND(R7>15100000,R7<=16950000),7,IF(AND(R7>16950000,R7<=19750000),8,IF(AND(R7>19750000,R7<=24150000),9,IF(AND(R7>24150000,R7<=26450000),10,IF(AND(R7>26450000,R7<=28000000),11,IF(AND(R7>28000000,R7<=30050000),12,IF(AND(R7>30050000,R7<=32400000),13,IF(AND(R7>32400000,R7<=35400000),14,IF(AND(R7>35400000,R7<=39100000),15,IF(AND(R7>39100000,R7<=43850000),16,IF(AND(R7>43850000,R7<=47800000),17,IF(AND(R7>47800000,R7<=51400000),18,IF(AND(R7>51400000,R7<=56300000),19,IF(AND(R7>56300000,R7<=62200000),20,IF(AND(R7>62200000,R7<=68600000),21,IF(AND(R7>68600000,R7<=77500000),22,IF(AND(R7>77500000,R7<=89000000),23,IF(AND(R7>89000000,R7<=103000000),24,IF(AND(R7>103000000,R7<=125000000),25,IF(AND(R7>125000000,R7<=157000000),26,IF(AND(R7>157000000,R7<=206000000),27,IF(AND(R7>206000000,R7<=337000000),28,IF(AND(R7>337000000,R7<=454000000),29,IF(AND(R7>454000000,R7<=550000000),30,IF(AND(R7>550000000,R7<=695000000),31,IF(AND(R7>695000000,R7<=910000000),32,IF(AND(R7>910000000,R7<=1400000000),33,34))))))))))))))))))))))))))))))))))))))))))) -> 0.75 | U7: =IF(R7<=6200000,0,IF(AND(R7>6200000,R7<=6500000),0.25,IF(AND(R7>6500000,R7<=6850000),0.5,IF(AND(R7>6850000,R7<=7300000),0.75,IF(AND(R7>7300000,R7<=9200000),1,IF(AND(R7>9200000,R7<=10750000),1.5,IF(AND(R7>10750000,R7<=11250000),2,IF(AND(R7>11250000,R7<=11600000),2.5,IF(AND(R7>11600000,R7<=12600000),3,IF(AND(R7>12600000,R7<=13600000),4,IF(AND(R7>13600000,R7<=14950000),5,IF(AND(R7>14950000,R7<=16400000),6,IF(AND(R7>16400000,R7<=18450000),7,IF(AND(R7>18450000,R7<=21850000),8,IF(AND(R7>21850000,R7<=26000000),9,IF(AND(R7>26000000,R7<=27700000),10,IF(AND(R7>27700000,R7<=29350000),11,IF(AND(R7>29350000,R7<=31450000),12,IF(AND(R7>31450000,R7<=33950000),13,IF(AND(R7>33950000,R7<=37100000),14,IF(AND(R7>37100000,R7<=41100000),15,IF(AND(R7>41100000,R7<=45800000),16,IF(AND(R7>45800000,R7<=49500000),17,IF(AND(R7>49500000,R7<=53800000),18,IF(AND(R7>53800000,R7<=58500000),19,IF(AND(R7>58500000,R7<=64000000),20,IF(AND(R7>64000000,R7<=71000000),21,IF(AND(R7>71000000,R7<=80000000),22,IF(AND(R7>80000000,R7<=93000000),23,IF(AND(R7>93000000,R7<=109000000),24,IF(AND(R7>109000000,R7<=129000000),25,IF(AND(R7>129000000,R7<=163000000),26,IF(AND(R7>163000000,R7<=211000000),27,IF(AND(R7>211000000,R7<=374000000),28,IF(AND(R7>374000000,R7<=459000000),29,IF(AND(R7>459000000,R7<=555000000),30,IF(AND(R7>555000000,R7<=704000000),31,IF(AND(R7>704000000,R7<=957000000),32,IF(AND(R7>957000000,R7<=1405000000),33,34))))))))))))))))))))))))))))))))))))))) -> 0.25 | V7: =IF(R7<=6600000,0,IF(AND(R7>6600000,R7<=6950000),0.25,IF(AND(R7>6950000,R7<=7350000),0.5,IF(AND(R7>7350000,R7<=7800000),0.75,IF(AND(R7>7800000,R7<=8850000),1,IF(AND(R7>8850000,R7<=9800000),1.25,IF(AND(R7>9800000,R7<=10950000),1.5,IF(AND(R7>10950000,R7<=11200000),1.75,IF(AND(R7>11200000,R7<=12050000),2,IF(AND(R7>12050000,R7<=12950000),3,IF(AND(R7>12950000,R7<=14150000),4,IF(AND(R7>14150000,R7<=15550000),5,IF(AND(R7>15550000,R7<=17050000),6,IF(AND(R7>17050000,R7<=19500000),7,IF(AND(R7>19500000,R7<=22700000),8,IF(AND(R7>22700000,R7<=26600000),9,IF(AND(R7>26600000,R7<=28100000),10,IF(AND(R7>28100000,R7<=30100000),11,IF(AND(R7>30100000,R7<=32600000),12,IF(AND(R7>32600000,R7<=35400000),13,IF(AND(R7>35400000,R7<=38900000),14,IF(AND(R7>38900000,R7<=43000000),15,IF(AND(R7>43000000,R7<=47400000),16,IF(AND(R7>47400000,R7<=51200000),17,IF(AND(R7>51200000,R7<=55800000),18,IF(AND(R7>55800000,R7<=60400000),19,IF(AND(R7>60400000,R7<=66700000),20,IF(AND(R7>66700000,R7<=74500000),21,IF(AND(R7>74500000,R7<=83200000),22,IF(AND(R7>83200000,R7<=95600000),23,IF(AND(R7>95600000,R7<=110000000),24,IF(AND(R7>110000000,R7<=134000000),25,IF(AND(R7>134000000,R7<=169000000),26,IF(AND(R7>169000000,R7<=221000000),27,IF(AND(R7>221000000,R7<=390000000),28,IF(AND(R7>390000000,R7<=463000000),29,IF(AND(R7>463000000,R7<=561000000),30,IF(AND(R7>561000000,R7<=709000000),31,IF(AND(R7>709000000,R7<=965000000),32,IF(AND(R7>965000000,R7<=1419000000),33,34)))))))))))))))))))))))))))))))))))))))) -> 0 | W7: =IF(R7<=60000000,5,IF(AND(R7>60000000,R7<=250000000),15,IF(AND(R7>250000000,R7<=500000000),25,IF(AND(R7>500000000,R7<=5000000000),30,35)))) -> 5 | X7: =IF(R7<=450000,0,IF(AND(R7>450000,R7<=2500000),0.5,0)) -> 0 | Y7: =IF(R7<=50000000,0,IF(AND(R7>50000000,R7<=100000000),5,IF(AND(R7>100000000,R7<=500000000),15,25))) -> 0 | Z7: =IF(R7<=50000000,0,5) -> 0
B8: 5 | C8: 2026 | D8: 3276016501040002 | E8: 3276016501040002000000 | F8: TK/0 | G8: N/A | H8: 21-100-35 | I8: 6035754.6 | J8: =VLOOKUP(H8,REF!$A$2:$D$33,3,0) -> 100 | K8: =IF(S8="TER",IF(OR(F8="TK/0",F8="TK/1",F8="K/0",F8="HB/0",F8="HB/1"),T8,IF(OR(F8="TK/2",F8="TK/3",F8="K/1",F8="K/2",F8="HB/2",F8="HB/3"),U8,V8)),IF(S8="PS17",W8,IF(S8="HARIAN",X8,IF(S8="PESANGON",Y8,IF(S8="PENSIUN",Z8,S8))))) -> 0.75 | L8: Other | M8: - | N8: 46173 | O8: 0668176225064000000000 | P8: 46173 | R8: =Table1[[#This Row],[Penghasilan]]*Table1[[#This Row],[Deemed]]/100 -> 6035754.6 | S8: =VLOOKUP(H8,REF!$A$2:$D$43,4,0) -> TER | T8: =IF(R8<=5400000,0,IF(AND(R8>5400000,R8<=5650000),0.25,IF(AND(R8>5650000,R8<=5950000),0.5,IF(AND(R8>5950000,R8<=6300000),0.75,IF(AND(R8>6300000,R8<=6750000),1,IF(AND(R8>6750000,R8<=7500000),1.25,IF(AND(R8>7500000,R8<=8550000),1.5,IF(AND(R8>8550000,R8<=9650000),1.75,IF(AND(R8>9650000,R8<=10050000),2,IF(AND(R8>10050000,R8<=10350000),2.25,IF(AND(R8>10350000,R8<=10700000),2.5,IF(AND(R8>10700000,R8<=11050000),3,IF(AND(R8>11050000,R8<=11600000),3.5,IF(AND(R8>11600000,R8<=12500000),4,IF(AND(R8>12500000,R8<=13750000),5,IF(AND(R8>13750000,R8<=15100000),6,IF(AND(R8>15100000,R8<=16950000),7,IF(AND(R8>16950000,R8<=19750000),8,IF(AND(R8>19750000,R8<=24150000),9,IF(AND(R8>24150000,R8<=26450000),10,IF(AND(R8>26450000,R8<=28000000),11,IF(AND(R8>28000000,R8<=30050000),12,IF(AND(R8>30050000,R8<=32400000),13,IF(AND(R8>32400000,R8<=35400000),14,IF(AND(R8>35400000,R8<=39100000),15,IF(AND(R8>39100000,R8<=43850000),16,IF(AND(R8>43850000,R8<=47800000),17,IF(AND(R8>47800000,R8<=51400000),18,IF(AND(R8>51400000,R8<=56300000),19,IF(AND(R8>56300000,R8<=62200000),20,IF(AND(R8>62200000,R8<=68600000),21,IF(AND(R8>68600000,R8<=77500000),22,IF(AND(R8>77500000,R8<=89000000),23,IF(AND(R8>89000000,R8<=103000000),24,IF(AND(R8>103000000,R8<=125000000),25,IF(AND(R8>125000000,R8<=157000000),26,IF(AND(R8>157000000,R8<=206000000),27,IF(AND(R8>206000000,R8<=337000000),28,IF(AND(R8>337000000,R8<=454000000),29,IF(AND(R8>454000000,R8<=550000000),30,IF(AND(R8>550000000,R8<=695000000),31,IF(AND(R8>695000000,R8<=910000000),32,IF(AND(R8>910000000,R8<=1400000000),33,34))))))))))))))))))))))))))))))))))))))))))) -> 0.75 | U8: =IF(R8<=6200000,0,IF(AND(R8>6200000,R8<=6500000),0.25,IF(AND(R8>6500000,R8<=6850000),0.5,IF(AND(R8>6850000,R8<=7300000),0.75,IF(AND(R8>7300000,R8<=9200000),1,IF(AND(R8>9200000,R8<=10750000),1.5,IF(AND(R8>10750000,R8<=11250000),2,IF(AND(R8>11250000,R8<=11600000),2.5,IF(AND(R8>11600000,R8<=12600000),3,IF(AND(R8>12600000,R8<=13600000),4,IF(AND(R8>13600000,R8<=14950000),5,IF(AND(R8>14950000,R8<=16400000),6,IF(AND(R8>16400000,R8<=18450000),7,IF(AND(R8>18450000,R8<=21850000),8,IF(AND(R8>21850000,R8<=26000000),9,IF(AND(R8>26000000,R8<=27700000),10,IF(AND(R8>27700000,R8<=29350000),11,IF(AND(R8>29350000,R8<=31450000),12,IF(AND(R8>31450000,R8<=33950000),13,IF(AND(R8>33950000,R8<=37100000),14,IF(AND(R8>37100000,R8<=41100000),15,IF(AND(R8>41100000,R8<=45800000),16,IF(AND(R8>45800000,R8<=49500000),17,IF(AND(R8>49500000,R8<=53800000),18,IF(AND(R8>53800000,R8<=58500000),19,IF(AND(R8>58500000,R8<=64000000),20,IF(AND(R8>64000000,R8<=71000000),21,IF(AND(R8>71000000,R8<=80000000),22,IF(AND(R8>80000000,R8<=93000000),23,IF(AND(R8>93000000,R8<=109000000),24,IF(AND(R8>109000000,R8<=129000000),25,IF(AND(R8>129000000,R8<=163000000),26,IF(AND(R8>163000000,R8<=211000000),27,IF(AND(R8>211000000,R8<=374000000),28,IF(AND(R8>374000000,R8<=459000000),29,IF(AND(R8>459000000,R8<=555000000),30,IF(AND(R8>555000000,R8<=704000000),31,IF(AND(R8>704000000,R8<=957000000),32,IF(AND(R8>957000000,R8<=1405000000),33,34))))))))))))))))))))))))))))))))))))))) -> 0 | V8: =IF(R8<=6600000,0,IF(AND(R8>6600000,R8<=6950000),0.25,IF(AND(R8>6950000,R8<=7350000),0.5,IF(AND(R8>7350000,R8<=7800000),0.75,IF(AND(R8>7800000,R8<=8850000),1,IF(AND(R8>8850000,R8<=9800000),1.25,IF(AND(R8>9800000,R8<=10950000),1.5,IF(AND(R8>10950000,R8<=11200000),1.75,IF(AND(R8>11200000,R8<=12050000),2,IF(AND(R8>12050000,R8<=12950000),3,IF(AND(R8>12950000,R8<=14150000),4,IF(AND(R8>14150000,R8<=15550000),5,IF(AND(R8>15550000,R8<=17050000),6,IF(AND(R8>17050000,R8<=19500000),7,IF(AND(R8>19500000,R8<=22700000),8,IF(AND(R8>22700000,R8<=26600000),9,IF(AND(R8>26600000,R8<=28100000),10,IF(AND(R8>28100000,R8<=30100000),11,IF(AND(R8>30100000,R8<=32600000),12,IF(AND(R8>32600000,R8<=35400000),13,IF(AND(R8>35400000,R8<=38900000),14,IF(AND(R8>38900000,R8<=43000000),15,IF(AND(R8>43000000,R8<=47400000),16,IF(AND(R8>47400000,R8<=51200000),17,IF(AND(R8>51200000,R8<=55800000),18,IF(AND(R8>55800000,R8<=60400000),19,IF(AND(R8>60400000,R8<=66700000),20,IF(AND(R8>66700000,R8<=74500000),21,IF(AND(R8>74500000,R8<=83200000),22,IF(AND(R8>83200000,R8<=95600000),23,IF(AND(R8>95600000,R8<=110000000),24,IF(AND(R8>110000000,R8<=134000000),25,IF(AND(R8>134000000,R8<=169000000),26,IF(AND(R8>169000000,R8<=221000000),27,IF(AND(R8>221000000,R8<=390000000),28,IF(AND(R8>390000000,R8<=463000000),29,IF(AND(R8>463000000,R8<=561000000),30,IF(AND(R8>561000000,R8<=709000000),31,IF(AND(R8>709000000,R8<=965000000),32,IF(AND(R8>965000000,R8<=1419000000),33,34)))))))))))))))))))))))))))))))))))))))) -> 0 | W8: =IF(R8<=60000000,5,IF(AND(R8>60000000,R8<=250000000),15,IF(AND(R8>250000000,R8<=500000000),25,IF(AND(R8>500000000,R8<=5000000000),30,35)))) -> 5 | X8: =IF(R8<=450000,0,IF(AND(R8>450000,R8<=2500000),0.5,0)) -> 0 | Y8: =IF(R8<=50000000,0,IF(AND(R8>50000000,R8<=100000000),5,IF(AND(R8>100000000,R8<=500000000),15,25))) -> 0 | Z8: =IF(R8<=50000000,0,5) -> 0
B9: 5 | C9: 2026 | D9: 3276014206040002 | E9: 3276014206040002000000 | F9: TK/0 | G9: N/A | H9: 21-100-35 | I9: 6298837.8 | J9: =VLOOKUP(H9,REF!$A$2:$D$33,3,0) -> 100 | K9: =IF(S9="TER",IF(OR(F9="TK/0",F9="TK/1",F9="K/0",F9="HB/0",F9="HB/1"),T9,IF(OR(F9="TK/2",F9="TK/3",F9="K/1",F9="K/2",F9="HB/2",F9="HB/3"),U9,V9)),IF(S9="PS17",W9,IF(S9="HARIAN",X9,IF(S9="PESANGON",Y9,IF(S9="PENSIUN",Z9,S9))))) -> 0.75 | L9: Other | M9: - | N9: 46173 | O9: 0668176225064000000000 | P9: 46173 | R9: =Table1[[#This Row],[Penghasilan]]*Table1[[#This Row],[Deemed]]/100 -> 6298837.8 | S9: =VLOOKUP(H9,REF!$A$2:$D$43,4,0) -> TER | T9: =IF(R9<=5400000,0,IF(AND(R9>5400000,R9<=5650000),0.25,IF(AND(R9>5650000,R9<=5950000),0.5,IF(AND(R9>5950000,R9<=6300000),0.75,IF(AND(R9>6300000,R9<=6750000),1,IF(AND(R9>6750000,R9<=7500000),1.25,IF(AND(R9>7500000,R9<=8550000),1.5,IF(AND(R9>8550000,R9<=9650000),1.75,IF(AND(R9>9650000,R9<=10050000),2,IF(AND(R9>10050000,R9<=10350000),2.25,IF(AND(R9>10350000,R9<=10700000),2.5,IF(AND(R9>10700000,R9<=11050000),3,IF(AND(R9>11050000,R9<=11600000),3.5,IF(AND(R9>11600000,R9<=12500000),4,IF(AND(R9>12500000,R9<=13750000),5,IF(AND(R9>13750000,R9<=15100000),6,IF(AND(R9>15100000,R9<=16950000),7,IF(AND(R9>16950000,R9<=19750000),8,IF(AND(R9>19750000,R9<=24150000),9,IF(AND(R9>24150000,R9<=26450000),10,IF(AND(R9>26450000,R9<=28000000),11,IF(AND(R9>28000000,R9<=30050000),12,IF(AND(R9>30050000,R9<=32400000),13,IF(AND(R9>32400000,R9<=35400000),14,IF(AND(R9>35400000,R9<=39100000),15,IF(AND(R9>39100000,R9<=43850000),16,IF(AND(R9>43850000,R9<=47800000),17,IF(AND(R9>47800000,R9<=51400000),18,IF(AND(R9>51400000,R9<=56300000),19,IF(AND(R9>56300000,R9<=62200000),20,IF(AND(R9>62200000,R9<=68600000),21,IF(AND(R9>68600000,R9<=77500000),22,IF(AND(R9>77500000,R9<=89000000),23,IF(AND(R9>89000000,R9<=103000000),24,IF(AND(R9>103000000,R9<=125000000),25,IF(AND(R9>125000000,R9<=157000000),26,IF(AND(R9>157000000,R9<=206000000),27,IF(AND(R9>206000000,R9<=337000000),28,IF(AND(R9>337000000,R9<=454000000),29,IF(AND(R9>454000000,R9<=550000000),30,IF(AND(R9>550000000,R9<=695000000),31,IF(AND(R9>695000000,R9<=910000000),32,IF(AND(R9>910000000,R9<=1400000000),33,34))))))))))))))))))))))))))))))))))))))))))) -> 0.75 | U9: =IF(R9<=6200000,0,IF(AND(R9>6200000,R9<=6500000),0.25,IF(AND(R9>6500000,R9<=6850000),0.5,IF(AND(R9>6850000,R9<=7300000),0.75,IF(AND(R9>7300000,R9<=9200000),1,IF(AND(R9>9200000,R9<=10750000),1.5,IF(AND(R9>10750000,R9<=11250000),2,IF(AND(R9>11250000,R9<=11600000),2.5,IF(AND(R9>11600000,R9<=12600000),3,IF(AND(R9>12600000,R9<=13600000),4,IF(AND(R9>13600000,R9<=14950000),5,IF(AND(R9>14950000,R9<=16400000),6,IF(AND(R9>16400000,R9<=18450000),7,IF(AND(R9>18450000,R9<=21850000),8,IF(AND(R9>21850000,R9<=26000000),9,IF(AND(R9>26000000,R9<=27700000),10,IF(AND(R9>27700000,R9<=29350000),11,IF(AND(R9>29350000,R9<=31450000),12,IF(AND(R9>31450000,R9<=33950000),13,IF(AND(R9>33950000,R9<=37100000),14,IF(AND(R9>37100000,R9<=41100000),15,IF(AND(R9>41100000,R9<=45800000),16,IF(AND(R9>45800000,R9<=49500000),17,IF(AND(R9>49500000,R9<=53800000),18,IF(AND(R9>53800000,R9<=58500000),19,IF(AND(R9>58500000,R9<=64000000),20,IF(AND(R9>64000000,R9<=71000000),21,IF(AND(R9>71000000,R9<=80000000),22,IF(AND(R9>80000000,R9<=93000000),23,IF(AND(R9>93000000,R9<=109000000),24,IF(AND(R9>109000000,R9<=129000000),25,IF(AND(R9>129000000,R9<=163000000),26,IF(AND(R9>163000000,R9<=211000000),27,IF(AND(R9>211000000,R9<=374000000),28,IF(AND(R9>374000000,R9<=459000000),29,IF(AND(R9>459000000,R9<=555000000),30,IF(AND(R9>555000000,R9<=704000000),31,IF(AND(R9>704000000,R9<=957000000),32,IF(AND(R9>957000000,R9<=1405000000),33,34))))))))))))))))))))))))))))))))))))))) -> 0.25 | V9: =IF(R9<=6600000,0,IF(AND(R9>6600000,R9<=6950000),0.25,IF(AND(R9>6950000,R9<=7350000),0.5,IF(AND(R9>7350000,R9<=7800000),0.75,IF(AND(R9>7800000,R9<=8850000),1,IF(AND(R9>8850000,R9<=9800000),1.25,IF(AND(R9>9800000,R9<=10950000),1.5,IF(AND(R9>10950000,R9<=11200000),1.75,IF(AND(R9>11200000,R9<=12050000),2,IF(AND(R9>12050000,R9<=12950000),3,IF(AND(R9>12950000,R9<=14150000),4,IF(AND(R9>14150000,R9<=15550000),5,IF(AND(R9>15550000,R9<=17050000),6,IF(AND(R9>17050000,R9<=19500000),7,IF(AND(R9>19500000,R9<=22700000),8,IF(AND(R9>22700000,R9<=26600000),9,IF(AND(R9>26600000,R9<=28100000),10,IF(AND(R9>28100000,R9<=30100000),11,IF(AND(R9>30100000,R9<=32600000),12,IF(AND(R9>32600000,R9<=35400000),13,IF(AND(R9>35400000,R9<=38900000),14,IF(AND(R9>38900000,R9<=43000000),15,IF(AND(R9>43000000,R9<=47400000),16,IF(AND(R9>47400000,R9<=51200000),17,IF(AND(R9>51200000,R9<=55800000),18,IF(AND(R9>55800000,R9<=60400000),19,IF(AND(R9>60400000,R9<=66700000),20,IF(AND(R9>66700000,R9<=74500000),21,IF(AND(R9>74500000,R9<=83200000),22,IF(AND(R9>83200000,R9<=95600000),23,IF(AND(R9>95600000,R9<=110000000),24,IF(AND(R9>110000000,R9<=134000000),25,IF(AND(R9>134000000,R9<=169000000),26,IF(AND(R9>169000000,R9<=221000000),27,IF(AND(R9>221000000,R9<=390000000),28,IF(AND(R9>390000000,R9<=463000000),29,IF(AND(R9>463000000,R9<=561000000),30,IF(AND(R9>561000000,R9<=709000000),31,IF(AND(R9>709000000,R9<=965000000),32,IF(AND(R9>965000000,R9<=1419000000),33,34)))))))))))))))))))))))))))))))))))))))) -> 0 | W9: =IF(R9<=60000000,5,IF(AND(R9>60000000,R9<=250000000),15,IF(AND(R9>250000000,R9<=500000000),25,IF(AND(R9>500000000,R9<=5000000000),30,35)))) -> 5 | X9: =IF(R9<=450000,0,IF(AND(R9>450000,R9<=2500000),0.5,0)) -> 0 | Y9: =IF(R9<=50000000,0,IF(AND(R9>50000000,R9<=100000000),5,IF(AND(R9>100000000,R9<=500000000),15,25))) -> 0 | Z9: =IF(R9<=50000000,0,5) -> 0
B10: 5 | C10: 2026 | D10: 3275010901050001 | E10: 3275010901050001000000 | F10: TK/0 | G10: N/A | H10: 21-100-35 | I10: 1479422.7 | J10: =VLOOKUP(H10,REF!$A$2:$D$33,3,0) -> 100 | K10: =IF(S10="TER",IF(OR(F10="TK/0",F10="TK/1",F10="K/0",F10="HB/0",F10="HB/1"),T10,IF(OR(F10="TK/2",F10="TK/3",F10="K/1",F10="K/2",F10="HB/2",F10="HB/3"),U10,V10)),IF(S10="PS17",W10,IF(S10="HARIAN",X10,IF(S10="PESANGON",Y10,IF(S10="PENSIUN",Z10,S10))))) -> 0 | L10: Other | M10: - | N10: 46173 | O10: 0668176225064000000000 | P10: 46173 | R10: =Table1[[#This Row],[Penghasilan]]*Table1[[#This Row],[Deemed]]/100 -> 1479422.7 | S10: =VLOOKUP(H10,REF!$A$2:$D$43,4,0) -> TER | T10: =IF(R10<=5400000,0,IF(AND(R10>5400000,R10<=5650000),0.25,IF(AND(R10>5650000,R10<=5950000),0.5,IF(AND(R10>5950000,R10<=6300000),0.75,IF(AND(R10>6300000,R10<=6750000),1,IF(AND(R10>6750000,R10<=7500000),1.25,IF(AND(R10>7500000,R10<=8550000),1.5,IF(AND(R10>8550000,R10<=9650000),1.75,IF(AND(R10>9650000,R10<=10050000),2,IF(AND(R10>10050000,R10<=10350000),2.25,IF(AND(R10>10350000,R10<=10700000),2.5,IF(AND(R10>10700000,R10<=11050000),3,IF(AND(R10>11050000,R10<=11600000),3.5,IF(AND(R10>11600000,R10<=12500000),4,IF(AND(R10>12500000,R10<=13750000),5,IF(AND(R10>13750000,R10<=15100000),6,IF(AND(R10>15100000,R10<=16950000),7,IF(AND(R10>16950000,R10<=19750000),8,IF(AND(R10>19750000,R10<=24150000),9,IF(AND(R10>24150000,R10<=26450000),10,IF(AND(R10>26450000,R10<=28000000),11,IF(AND(R10>28000000,R10<=30050000),12,IF(AND(R10>30050000,R10<=32400000),13,IF(AND(R10>32400000,R10<=35400000),14,IF(AND(R10>35400000,R10<=39100000),15,IF(AND(R10>39100000,R10<=43850000),16,IF(AND(R10>43850000,R10<=47800000),17,IF(AND(R10>47800000,R10<=51400000),18,IF(AND(R10>51400000,R10<=56300000),19,IF(AND(R10>56300000,R10<=62200000),20,IF(AND(R10>62200000,R10<=68600000),21,IF(AND(R10>68600000,R10<=77500000),22,IF(AND(R10>77500000,R10<=89000000),23,IF(AND(R10>89000000,R10<=103000000),24,IF(AND(R10>103000000,R10<=125000000),25,IF(AND(R10>125000000,R10<=157000000),26,IF(AND(R10>157000000,R10<=206000000),27,IF(AND(R10>206000000,R10<=337000000),28,IF(AND(R10>337000000,R10<=454000000),29,IF(AND(R10>454000000,R10<=550000000),30,IF(AND(R10>550000000,R10<=695000000),31,IF(AND(R10>695000000,R10<=910000000),32,IF(AND(R10>910000000,R10<=1400000000),33,34))))))))))))))))))))))))))))))))))))))))))) -> 0 | U10: =IF(R10<=6200000,0,IF(AND(R10>6200000,R10<=6500000),0.25,IF(AND(R10>6500000,R10<=6850000),0.5,IF(AND(R10>6850000,R10<=7300000),0.75,IF(AND(R10>7300000,R10<=9200000),1,IF(AND(R10>9200000,R10<=10750000),1.5,IF(AND(R10>10750000,R10<=11250000),2,IF(AND(R10>11250000,R10<=11600000),2.5,IF(AND(R10>11600000,R10<=12600000),3,IF(AND(R10>12600000,R10<=13600000),4,IF(AND(R10>13600000,R10<=14950000),5,IF(AND(R10>14950000,R10<=16400000),6,IF(AND(R10>16400000,R10<=18450000),7,IF(AND(R10>18450000,R10<=21850000),8,IF(AND(R10>21850000,R10<=26000000),9,IF(AND(R10>26000000,R10<=27700000),10,IF(AND(R10>27700000,R10<=29350000),11,IF(AND(R10>29350000,R10<=31450000),12,IF(AND(R10>31450000,R10<=33950000),13,IF(AND(R10>33950000,R10<=37100000),14,IF(AND(R10>37100000,R10<=41100000),15,IF(AND(R10>41100000,R10<=45800000),16,IF(AND(R10>45800000,R10<=49500000),17,IF(AND(R10>49500000,R10<=53800000),18,IF(AND(R10>53800000,R10<=58500000),19,IF(AND(R10>58500000,R10<=64000000),20,IF(AND(R10>64000000,R10<=71000000),21,IF(AND(R10>71000000,R10<=80000000),22,IF(AND(R10>80000000,R10<=93000000),23,IF(AND(R10>93000000,R10<=109000000),24,IF(AND(R10>109000000,R10<=129000000),25,IF(AND(R10>129000000,R10<=163000000),26,IF(AND(R10>163000000,R10<=211000000),27,IF(AND(R10>211000000,R10<=374000000),28,IF(AND(R10>374000000,R10<=459000000),29,IF(AND(R10>459000000,R10<=555000000),30,IF(AND(R10>555000000,R10<=704000000),31,IF(AND(R10>704000000,R10<=957000000),32,IF(AND(R10>957000000,R10<=1405000000),33,34))))))))))))))))))))))))))))))))))))))) -> 0 | V10: =IF(R10<=6600000,0,IF(AND(R10>6600000,R10<=6950000),0.25,IF(AND(R10>6950000,R10<=7350000),0.5,IF(AND(R10>7350000,R10<=7800000),0.75,IF(AND(R10>7800000,R10<=8850000),1,IF(AND(R10>8850000,R10<=9800000),1.25,IF(AND(R10>9800000,R10<=10950000),1.5,IF(AND(R10>10950000,R10<=11200000),1.75,IF(AND(R10>11200000,R10<=12050000),2,IF(AND(R10>12050000,R10<=12950000),3,IF(AND(R10>12950000,R10<=14150000),4,IF(AND(R10>14150000,R10<=15550000),5,IF(AND(R10>15550000,R10<=17050000),6,IF(AND(R10>17050000,R10<=19500000),7,IF(AND(R10>19500000,R10<=22700000),8,IF(AND(R10>22700000,R10<=26600000),9,IF(AND(R10>26600000,R10<=28100000),10,IF(AND(R10>28100000,R10<=30100000),11,IF(AND(R10>30100000,R10<=32600000),12,IF(AND(R10>32600000,R10<=35400000),13,IF(AND(R10>35400000,R10<=38900000),14,IF(AND(R10>38900000,R10<=43000000),15,IF(AND(R10>43000000,R10<=47400000),16,IF(AND(R10>47400000,R10<=51200000),17,IF(AND(R10>51200000,R10<=55800000),18,IF(AND(R10>55800000,R10<=60400000),19,IF(AND(R10>60400000,R10<=66700000),20,IF(AND(R10>66700000,R10<=74500000),21,IF(AND(R10>74500000,R10<=83200000),22,IF(AND(R10>83200000,R10<=95600000),23,IF(AND(R10>95600000,R10<=110000000),24,IF(AND(R10>110000000,R10<=134000000),25,IF(AND(R10>134000000,R10<=169000000),26,IF(AND(R10>169000000,R10<=221000000),27,IF(AND(R10>221000000,R10<=390000000),28,IF(AND(R10>390000000,R10<=463000000),29,IF(AND(R10>463000000,R10<=561000000),30,IF(AND(R10>561000000,R10<=709000000),31,IF(AND(R10>709000000,R10<=965000000),32,IF(AND(R10>965000000,R10<=1419000000),33,34)))))))))))))))))))))))))))))))))))))))) -> 0 | W10: =IF(R10<=60000000,5,IF(AND(R10>60000000,R10<=250000000),15,IF(AND(R10>250000000,R10<=500000000),25,IF(AND(R10>500000000,R10<=5000000000),30,35)))) -> 5 | X10: =IF(R10<=450000,0,IF(AND(R10>450000,R10<=2500000),0.5,0)) -> 0.5 | Y10: =IF(R10<=50000000,0,IF(AND(R10>50000000,R10<=100000000),5,IF(AND(R10>100000000,R10<=500000000),15,25))) -> 0 | Z10: =IF(R10<=50000000,0,5) -> 0
B11: 5 | C11: 2026 | D11: 3305096106040002 | E11: 3305096106040002000000 | F11: TK/0 | G11: N/A | H11: 21-100-35 | I11: 6009837.8 | J11: =VLOOKUP(H11,REF!$A$2:$D$33,3,0) -> 100 | K11: =IF(S11="TER",IF(OR(F11="TK/0",F11="TK/1",F11="K/0",F11="HB/0",F11="HB/1"),T11,IF(OR(F11="TK/2",F11="TK/3",F11="K/1",F11="K/2",F11="HB/2",F11="HB/3"),U11,V11)),IF(S11="PS17",W11,IF(S11="HARIAN",X11,IF(S11="PESANGON",Y11,IF(S11="PENSIUN",Z11,S11))))) -> 0.75 | L11: Other | M11: - | N11: 46173 | O11: 0668176225064000000000 | P11: 46173 | R11: =Table1[[#This Row],[Penghasilan]]*Table1[[#This Row],[Deemed]]/100 -> 6009837.8 | S11: =VLOOKUP(H11,REF!$A$2:$D$43,4,0) -> TER | T11: =IF(R11<=5400000,0,IF(AND(R11>5400000,R11<=5650000),0.25,IF(AND(R11>5650000,R11<=5950000),0.5,IF(AND(R11>5950000,R11<=6300000),0.75,IF(AND(R11>6300000,R11<=6750000),1,IF(AND(R11>6750000,R11<=7500000),1.25,IF(AND(R11>7500000,R11<=8550000),1.5,IF(AND(R11>8550000,R11<=9650000),1.75,IF(AND(R11>9650000,R11<=10050000),2,IF(AND(R11>10050000,R11<=10350000),2.25,IF(AND(R11>10350000,R11<=10700000),2.5,IF(AND(R11>10700000,R11<=11050000),3,IF(AND(R11>11050000,R11<=11600000),3.5,IF(AND(R11>11600000,R11<=12500000),4,IF(AND(R11>12500000,R11<=13750000),5,IF(AND(R11>13750000,R11<=15100000),6,IF(AND(R11>15100000,R11<=16950000),7,IF(AND(R11>16950000,R11<=19750000),8,IF(AND(R11>19750000,R11<=24150000),9,IF(AND(R11>24150000,R11<=26450000),10,IF(AND(R11>26450000,R11<=28000000),11,IF(AND(R11>28000000,R11<=30050000),12,IF(AND(R11>30050000,R11<=32400000),13,IF(AND(R11>32400000,R11<=35400000),14,IF(AND(R11>35400000,R11<=39100000),15,IF(AND(R11>39100000,R11<=43850000),16,IF(AND(R11>43850000,R11<=47800000),17,IF(AND(R11>47800000,R11<=51400000),18,IF(AND(R11>51400000,R11<=56300000),19,IF(AND(R11>56300000,R11<=62200000),20,IF(AND(R11>62200000,R11<=68600000),21,IF(AND(R11>68600000,R11<=77500000),22,IF(AND(R11>77500000,R11<=89000000),23,IF(AND(R11>89000000,R11<=103000000),24,IF(AND(R11>103000000,R11<=125000000),25,IF(AND(R11>125000000,R11<=157000000),26,IF(AND(R11>157000000,R11<=206000000),27,IF(AND(R11>206000000,R11<=337000000),28,IF(AND(R11>337000000,R11<=454000000),29,IF(AND(R11>454000000,R11<=550000000),30,IF(AND(R11>550000000,R11<=695000000),31,IF(AND(R11>695000000,R11<=910000000),32,IF(AND(R11>910000000,R11<=1400000000),33,34))))))))))))))))))))))))))))))))))))))))))) -> 0.75 | U11: =IF(R11<=6200000,0,IF(AND(R11>6200000,R11<=6500000),0.25,IF(AND(R11>6500000,R11<=6850000),0.5,IF(AND(R11>6850000,R11<=7300000),0.75,IF(AND(R11>7300000,R11<=9200000),1,IF(AND(R11>9200000,R11<=10750000),1.5,IF(AND(R11>10750000,R11<=11250000),2,IF(AND(R11>11250000,R11<=11600000),2.5,IF(AND(R11>11600000,R11<=12600000),3,IF(AND(R11>12600000,R11<=13600000),4,IF(AND(R11>13600000,R11<=14950000),5,IF(AND(R11>14950000,R11<=16400000),6,IF(AND(R11>16400000,R11<=18450000),7,IF(AND(R11>18450000,R11<=21850000),8,IF(AND(R11>21850000,R11<=26000000),9,IF(AND(R11>26000000,R11<=27700000),10,IF(AND(R11>27700000,R11<=29350000),11,IF(AND(R11>29350000,R11<=31450000),12,IF(AND(R11>31450000,R11<=33950000),13,IF(AND(R11>33950000,R11<=37100000),14,IF(AND(R11>37100000,R11<=41100000),15,IF(AND(R11>41100000,R11<=45800000),16,IF(AND(R11>45800000,R11<=49500000),17,IF(AND(R11>49500000,R11<=53800000),18,IF(AND(R11>53800000,R11<=58500000),19,IF(AND(R11>58500000,R11<=64000000),20,IF(AND(R11>64000000,R11<=71000000),21,IF(AND(R11>71000000,R11<=80000000),22,IF(AND(R11>80000000,R11<=93000000),23,IF(AND(R11>93000000,R11<=109000000),24,IF(AND(R11>109000000,R11<=129000000),25,IF(AND(R11>129000000,R11<=163000000),26,IF(AND(R11>163000000,R11<=211000000),27,IF(AND(R11>211000000,R11<=374000000),28,IF(AND(R11>374000000,R11<=459000000),29,IF(AND(R11>459000000,R11<=555000000),30,IF(AND(R11>555000000,R11<=704000000),31,IF(AND(R11>704000000,R11<=957000000),32,IF(AND(R11>957000000,R11<=1405000000),33,34))))))))))))))))))))))))))))))))))))))) -> 0 | V11: =IF(R11<=6600000,0,IF(AND(R11>6600000,R11<=6950000),0.25,IF(AND(R11>6950000,R11<=7350000),0.5,IF(AND(R11>7350000,R11<=7800000),0.75,IF(AND(R11>7800000,R11<=8850000),1,IF(AND(R11>8850000,R11<=9800000),1.25,IF(AND(R11>9800000,R11<=10950000),1.5,IF(AND(R11>10950000,R11<=11200000),1.75,IF(AND(R11>11200000,R11<=12050000),2,IF(AND(R11>12050000,R11<=12950000),3,IF(AND(R11>12950000,R11<=14150000),4,IF(AND(R11>14150000,R11<=15550000),5,IF(AND(R11>15550000,R11<=17050000),6,IF(AND(R11>17050000,R11<=19500000),7,IF(AND(R11>19500000,R11<=22700000),8,IF(AND(R11>22700000,R11<=26600000),9,IF(AND(R11>26600000,R11<=28100000),10,IF(AND(R11>28100000,R11<=30100000),11,IF(AND(R11>30100000,R11<=32600000),12,IF(AND(R11>32600000,R11<=35400000),13,IF(AND(R11>35400000,R11<=38900000),14,IF(AND(R11>38900000,R11<=43000000),15,IF(AND(R11>43000000,R11<=47400000),16,IF(AND(R11>47400000,R11<=51200000),17,IF(AND(R11>51200000,R11<=55800000),18,IF(AND(R11>55800000,R11<=60400000),19,IF(AND(R11>60400000,R11<=66700000),20,IF(AND(R11>66700000,R11<=74500000),21,IF(AND(R11>74500000,R11<=83200000),22,IF(AND(R11>83200000,R11<=95600000),23,IF(AND(R11>95600000,R11<=110000000),24,IF(AND(R11>110000000,R11<=134000000),25,IF(AND(R11>134000000,R11<=169000000),26,IF(AND(R11>169000000,R11<=221000000),27,IF(AND(R11>221000000,R11<=390000000),28,IF(AND(R11>390000000,R11<=463000000),29,IF(AND(R11>463000000,R11<=561000000),30,IF(AND(R11>561000000,R11<=709000000),31,IF(AND(R11>709000000,R11<=965000000),32,IF(AND(R11>965000000,R11<=1419000000),33,34)))))))))))))))))))))))))))))))))))))))) -> 0 | W11: =IF(R11<=60000000,5,IF(AND(R11>60000000,R11<=250000000),15,IF(AND(R11>250000000,R11<=500000000),25,IF(AND(R11>500000000,R11<=5000000000),30,35)))) -> 5 | X11: =IF(R11<=450000,0,IF(AND(R11>450000,R11<=2500000),0.5,0)) -> 0 | Y11: =IF(R11<=50000000,0,IF(AND(R11>50000000,R11<=100000000),5,IF(AND(R11>100000000,R11<=500000000),15,25))) -> 0 | Z11: =IF(R11<=50000000,0,5) -> 0
B12: 5 | C12: 2026 | D12: 3276015306040010 | E12: 3276015306040010000000 | F12: TK/0 | G12: N/A | H12: 21-100-35 | I12: 6052754.6 | J12: =VLOOKUP(H12,REF!$A$2:$D$33,3,0) -> 100 | K12: =IF(S12="TER",IF(OR(F12="TK/0",F12="TK/1",F12="K/0",F12="HB/0",F12="HB/1"),T12,IF(OR(F12="TK/2",F12="TK/3",F12="K/1",F12="K/2",F12="HB/2",F12="HB/3"),U12,V12)),IF(S12="PS17",W12,IF(S12="HARIAN",X12,IF(S12="PESANGON",Y12,IF(S12="PENSIUN",Z12,S12))))) -> 0.75 | L12: Other | M12: - | N12: 46173 | O12: 0668176225064000000000 | P12: 46173 | R12: =Table1[[#This Row],[Penghasilan]]*Table1[[#This Row],[Deemed]]/100 -> 6052754.6 | S12: =VLOOKUP(H12,REF!$A$2:$D$43,4,0) -> TER | T12: =IF(R12<=5400000,0,IF(AND(R12>5400000,R12<=5650000),0.25,IF(AND(R12>5650000,R12<=5950000),0.5,IF(AND(R12>5950000,R12<=6300000),0.75,IF(AND(R12>6300000,R12<=6750000),1,IF(AND(R12>6750000,R12<=7500000),1.25,IF(AND(R12>7500000,R12<=8550000),1.5,IF(AND(R12>8550000,R12<=9650000),1.75,IF(AND(R12>9650000,R12<=10050000),2,IF(AND(R12>10050000,R12<=10350000),2.25,IF(AND(R12>10350000,R12<=10700000),2.5,IF(AND(R12>10700000,R12<=11050000),3,IF(AND(R12>11050000,R12<=11600000),3.5,IF(AND(R12>11600000,R12<=12500000),4,IF(AND(R12>12500000,R12<=13750000),5,IF(AND(R12>13750000,R12<=15100000),6,IF(AND(R12>15100000,R12<=16950000),7,IF(AND(R12>16950000,R12<=19750000),8,IF(AND(R12>19750000,R12<=24150000),9,IF(AND(R12>24150000,R12<=26450000),10,IF(AND(R12>26450000,R12<=28000000),11,IF(AND(R12>28000000,R12<=30050000),12,IF(AND(R12>30050000,R12<=32400000),13,IF(AND(R12>32400000,R12<=35400000),14,IF(AND(R12>35400000,R12<=39100000),15,IF(AND(R12>39100000,R12<=43850000),16,IF(AND(R12>43850000,R12<=47800000),17,IF(AND(R12>47800000,R12<=51400000),18,IF(AND(R12>51400000,R12<=56300000),19,IF(AND(R12>56300000,R12<=62200000),20,IF(AND(R12>62200000,R12<=68600000),21,IF(AND(R12>68600000,R12<=77500000),22,IF(AND(R12>77500000,R12<=89000000),23,IF(AND(R12>89000000,R12<=103000000),24,IF(AND(R12>103000000,R12<=125000000),25,IF(AND(R12>125000000,R12<=157000000),26,IF(AND(R12>157000000,R12<=206000000),27,IF(AND(R12>206000000,R12<=337000000),28,IF(AND(R12>337000000,R12<=454000000),29,IF(AND(R12>454000000,R12<=550000000),30,IF(AND(R12>550000000,R12<=695000000),31,IF(AND(R12>695000000,R12<=910000000),32,IF(AND(R12>910000000,R12<=1400000000),33,34))))))))))))))))))))))))))))))))))))))))))) -> 0.75 | U12: =IF(R12<=6200000,0,IF(AND(R12>6200000,R12<=6500000),0.25,IF(AND(R12>6500000,R12<=6850000),0.5,IF(AND(R12>6850000,R12<=7300000),0.75,IF(AND(R12>7300000,R12<=9200000),1,IF(AND(R12>9200000,R12<=10750000),1.5,IF(AND(R12>10750000,R12<=11250000),2,IF(AND(R12>11250000,R12<=11600000),2.5,IF(AND(R12>11600000,R12<=12600000),3,IF(AND(R12>12600000,R12<=13600000),4,IF(AND(R12>13600000,R12<=14950000),5,IF(AND(R12>14950000,R12<=16400000),6,IF(AND(R12>16400000,R12<=18450000),7,IF(AND(R12>18450000,R12<=21850000),8,IF(AND(R12>21850000,R12<=26000000),9,IF(AND(R12>26000000,R12<=27700000),10,IF(AND(R12>27700000,R12<=29350000),11,IF(AND(R12>29350000,R12<=31450000),12,IF(AND(R12>31450000,R12<=33950000),13,IF(AND(R12>33950000,R12<=37100000),14,IF(AND(R12>37100000,R12<=41100000),15,IF(AND(R12>41100000,R12<=45800000),16,IF(AND(R12>45800000,R12<=49500000),17,IF(AND(R12>49500000,R12<=53800000),18,IF(AND(R12>53800000,R12<=58500000),19,IF(AND(R12>58500000,R12<=64000000),20,IF(AND(R12>64000000,R12<=71000000),21,IF(AND(R12>71000000,R12<=80000000),22,IF(AND(R12>80000000,R12<=93000000),23,IF(AND(R12>93000000,R12<=109000000),24,IF(AND(R12>109000000,R12<=129000000),25,IF(AND(R12>129000000,R12<=163000000),26,IF(AND(R12>163000000,R12<=211000000),27,IF(AND(R12>211000000,R12<=374000000),28,IF(AND(R12>374000000,R12<=459000000),29,IF(AND(R12>459000000,R12<=555000000),30,IF(AND(R12>555000000,R12<=704000000),31,IF(AND(R12>704000000,R12<=957000000),32,IF(AND(R12>957000000,R12<=1405000000),33,34))))))))))))))))))))))))))))))))))))))) -> 0 | V12: =IF(R12<=6600000,0,IF(AND(R12>6600000,R12<=6950000),0.25,IF(AND(R12>6950000,R12<=7350000),0.5,IF(AND(R12>7350000,R12<=7800000),0.75,IF(AND(R12>7800000,R12<=8850000),1,IF(AND(R12>8850000,R12<=9800000),1.25,IF(AND(R12>9800000,R12<=10950000),1.5,IF(AND(R12>10950000,R12<=11200000),1.75,IF(AND(R12>11200000,R12<=12050000),2,IF(AND(R12>12050000,R12<=12950000),3,IF(AND(R12>12950000,R12<=14150000),4,IF(AND(R12>14150000,R12<=15550000),5,IF(AND(R12>15550000,R12<=17050000),6,IF(AND(R12>17050000,R12<=19500000),7,IF(AND(R12>19500000,R12<=22700000),8,IF(AND(R12>22700000,R12<=26600000),9,IF(AND(R12>26600000,R12<=28100000),10,IF(AND(R12>28100000,R12<=30100000),11,IF(AND(R12>30100000,R12<=32600000),12,IF(AND(R12>32600000,R12<=35400000),13,IF(AND(R12>35400000,R12<=38900000),14,IF(AND(R12>38900000,R12<=43000000),15,IF(AND(R12>43000000,R12<=47400000),16,IF(AND(R12>47400000,R12<=51200000),17,IF(AND(R12>51200000,R12<=55800000),18,IF(AND(R12>55800000,R12<=60400000),19,IF(AND(R12>60400000,R12<=66700000),20,IF(AND(R12>66700000,R12<=74500000),21,IF(AND(R12>74500000,R12<=83200000),22,IF(AND(R12>83200000,R12<=95600000),23,IF(AND(R12>95600000,R12<=110000000),24,IF(AND(R12>110000000,R12<=134000000),25,IF(AND(R12>134000000,R12<=169000000),26,IF(AND(R12>169000000,R12<=221000000),27,IF(AND(R12>221000000,R12<=390000000),28,IF(AND(R12>390000000,R12<=463000000),29,IF(AND(R12>463000000,R12<=561000000),30,IF(AND(R12>561000000,R12<=709000000),31,IF(AND(R12>709000000,R12<=965000000),32,IF(AND(R12>965000000,R12<=1419000000),33,34)))))))))))))))))))))))))))))))))))))))) -> 0 | W12: =IF(R12<=60000000,5,IF(AND(R12>60000000,R12<=250000000),15,IF(AND(R12>250000000,R12<=500000000),25,IF(AND(R12>500000000,R12<=5000000000),30,35)))) -> 5 | X12: =IF(R12<=450000,0,IF(AND(R12>450000,R12<=2500000),0.5,0)) -> 0 | Y12: =IF(R12<=50000000,0,IF(AND(R12>50000000,R12<=100000000),5,IF(AND(R12>100000000,R12<=500000000),15,25))) -> 0 | Z12: =IF(R12<=50000000,0,5) -> 0
B13: 5 | C13: 2026 | D13: 3201370904050001 | E13: 3201370904050001000000 | F13: TK/0 | G13: N/A | H13: 21-100-35 | I13: 6213837.8 | J13: =VLOOKUP(H13,REF!$A$2:$D$33,3,0) -> 100 | K13: =IF(S13="TER",IF(OR(F13="TK/0",F13="TK/1",F13="K/0",F13="HB/0",F13="HB/1"),T13,IF(OR(F13="TK/2",F13="TK/3",F13="K/1",F13="K/2",F13="HB/2",F13="HB/3"),U13,V13)),IF(S13="PS17",W13,IF(S13="HARIAN",X13,IF(S13="PESANGON",Y13,IF(S13="PENSIUN",Z13,S13))))) -> 0.75 | L13: Other | M13: - | N13: 46173 | O13: 0668176225064000000000 | P13: 46173 | R13: =Table1[[#This Row],[Penghasilan]]*Table1[[#This Row],[Deemed]]/100 -> 6213837.8 | S13: =VLOOKUP(H13,REF!$A$2:$D$43,4,0) -> TER | T13: =IF(R13<=5400000,0,IF(AND(R13>5400000,R13<=5650000),0.25,IF(AND(R13>5650000,R13<=5950000),0.5,IF(AND(R13>5950000,R13<=6300000),0.75,IF(AND(R13>6300000,R13<=6750000),1,IF(AND(R13>6750000,R13<=7500000),1.25,IF(AND(R13>7500000,R13<=8550000),1.5,IF(AND(R13>8550000,R13<=9650000),1.75,IF(AND(R13>9650000,R13<=10050000),2,IF(AND(R13>10050000,R13<=10350000),2.25,IF(AND(R13>10350000,R13<=10700000),2.5,IF(AND(R13>10700000,R13<=11050000),3,IF(AND(R13>11050000,R13<=11600000),3.5,IF(AND(R13>11600000,R13<=12500000),4,IF(AND(R13>12500000,R13<=13750000),5,IF(AND(R13>13750000,R13<=15100000),6,IF(AND(R13>15100000,R13<=16950000),7,IF(AND(R13>16950000,R13<=19750000),8,IF(AND(R13>19750000,R13<=24150000),9,IF(AND(R13>24150000,R13<=26450000),10,IF(AND(R13>26450000,R13<=28000000),11,IF(AND(R13>28000000,R13<=30050000),12,IF(AND(R13>30050000,R13<=32400000),13,IF(AND(R13>32400000,R13<=35400000),14,IF(AND(R13>35400000,R13<=39100000),15,IF(AND(R13>39100000,R13<=43850000),16,IF(AND(R13>43850000,R13<=47800000),17,IF(AND(R13>47800000,R13<=51400000),18,IF(AND(R13>51400000,R13<=56300000),19,IF(AND(R13>56300000,R13<=62200000),20,IF(AND(R13>62200000,R13<=68600000),21,IF(AND(R13>68600000,R13<=77500000),22,IF(AND(R13>77500000,R13<=89000000),23,IF(AND(R13>89000000,R13<=103000000),24,IF(AND(R13>103000000,R13<=125000000),25,IF(AND(R13>125000000,R13<=157000000),26,IF(AND(R13>157000000,R13<=206000000),27,IF(AND(R13>206000000,R13<=337000000),28,IF(AND(R13>337000000,R13<=454000000),29,IF(AND(R13>454000000,R13<=550000000),30,IF(AND(R13>550000000,R13<=695000000),31,IF(AND(R13>695000000,R13<=910000000),32,IF(AND(R13>910000000,R13<=1400000000),33,34))))))))))))))))))))))))))))))))))))))))))) -> 0.75 | U13: =IF(R13<=6200000,0,IF(AND(R13>6200000,R13<=6500000),0.25,IF(AND(R13>6500000,R13<=6850000),0.5,IF(AND(R13>6850000,R13<=7300000),0.75,IF(AND(R13>7300000,R13<=9200000),1,IF(AND(R13>9200000,R13<=10750000),1.5,IF(AND(R13>10750000,R13<=11250000),2,IF(AND(R13>11250000,R13<=11600000),2.5,IF(AND(R13>11600000,R13<=12600000),3,IF(AND(R13>12600000,R13<=13600000),4,IF(AND(R13>13600000,R13<=14950000),5,IF(AND(R13>14950000,R13<=16400000),6,IF(AND(R13>16400000,R13<=18450000),7,IF(AND(R13>18450000,R13<=21850000),8,IF(AND(R13>21850000,R13<=26000000),9,IF(AND(R13>26000000,R13<=27700000),10,IF(AND(R13>27700000,R13<=29350000),11,IF(AND(R13>29350000,R13<=31450000),12,IF(AND(R13>31450000,R13<=33950000),13,IF(AND(R13>33950000,R13<=37100000),14,IF(AND(R13>37100000,R13<=41100000),15,IF(AND(R13>41100000,R13<=45800000),16,IF(AND(R13>45800000,R13<=49500000),17,IF(AND(R13>49500000,R13<=53800000),18,IF(AND(R13>53800000,R13<=58500000),19,IF(AND(R13>58500000,R13<=64000000),20,IF(AND(R13>64000000,R13<=71000000),21,IF(AND(R13>71000000,R13<=80000000),22,IF(AND(R13>80000000,R13<=93000000),23,IF(AND(R13>93000000,R13<=109000000),24,IF(AND(R13>109000000,R13<=129000000),25,IF(AND(R13>129000000,R13<=163000000),26,IF(AND(R13>163000000,R13<=211000000),27,IF(AND(R13>211000000,R13<=374000000),28,IF(AND(R13>374000000,R13<=459000000),29,IF(AND(R13>459000000,R13<=555000000),30,IF(AND(R13>555000000,R13<=704000000),31,IF(AND(R13>704000000,R13<=957000000),32,IF(AND(R13>957000000,R13<=1405000000),33,34))))))))))))))))))))))))))))))))))))))) -> 0.25 | V13: =IF(R13<=6600000,0,IF(AND(R13>6600000,R13<=6950000),0.25,IF(AND(R13>6950000,R13<=7350000),0.5,IF(AND(R13>7350000,R13<=7800000),0.75,IF(AND(R13>7800000,R13<=8850000),1,IF(AND(R13>8850000,R13<=9800000),1.25,IF(AND(R13>9800000,R13<=10950000),1.5,IF(AND(R13>10950000,R13<=11200000),1.75,IF(AND(R13>11200000,R13<=12050000),2,IF(AND(R13>12050000,R13<=12950000),3,IF(AND(R13>12950000,R13<=14150000),4,IF(AND(R13>14150000,R13<=15550000),5,IF(AND(R13>15550000,R13<=17050000),6,IF(AND(R13>17050000,R13<=19500000),7,IF(AND(R13>19500000,R13<=22700000),8,IF(AND(R13>22700000,R13<=26600000),9,IF(AND(R13>26600000,R13<=28100000),10,IF(AND(R13>28100000,R13<=30100000),11,IF(AND(R13>30100000,R13<=32600000),12,IF(AND(R13>32600000,R13<=35400000),13,IF(AND(R13>35400000,R13<=38900000),14,IF(AND(R13>38900000,R13<=43000000),15,IF(AND(R13>43000000,R13<=47400000),16,IF(AND(R13>47400000,R13<=51200000),17,IF(AND(R13>51200000,R13<=55800000),18,IF(AND(R13>55800000,R13<=60400000),19,IF(AND(R13>60400000,R13<=66700000),20,IF(AND(R13>66700000,R13<=74500000),21,IF(AND(R13>74500000,R13<=83200000),22,IF(AND(R13>83200000,R13<=95600000),23,IF(AND(R13>95600000,R13<=110000000),24,IF(AND(R13>110000000,R13<=134000000),25,IF(AND(R13>134000000,R13<=169000000),26,IF(AND(R13>169000000,R13<=221000000),27,IF(AND(R13>221000000,R13<=390000000),28,IF(AND(R13>390000000,R13<=463000000),29,IF(AND(R13>463000000,R13<=561000000),30,IF(AND(R13>561000000,R13<=709000000),31,IF(AND(R13>709000000,R13<=965000000),32,IF(AND(R13>965000000,R13<=1419000000),33,34)))))))))))))))))))))))))))))))))))))))) -> 0 | W13: =IF(R13<=60000000,5,IF(AND(R13>60000000,R13<=250000000),15,IF(AND(R13>250000000,R13<=500000000),25,IF(AND(R13>500000000,R13<=5000000000),30,35)))) -> 5 | X13: =IF(R13<=450000,0,IF(AND(R13>450000,R13<=2500000),0.5,0)) -> 0 | Y13: =IF(R13<=50000000,0,IF(AND(R13>50000000,R13<=100000000),5,IF(AND(R13>100000000,R13<=500000000),15,25))) -> 0 | Z13: =IF(R13<=50000000,0,5) -> 0
